Workbook

Sheet P1
A1: thisN | B1: key_resp.corr | C1: key_resp.rt | E1: seqRT | F1: ranRT
A2: 0 | B2: 1 | C2: 0.93258108 | E2: 0.93258108 | F2: 0.32668812
A3: 1 | B3: 1 | C3: 0.32266562 | E3: 0.32266562 | F3: 0.57620929
A4: 2 | B4: 1 | C4: 0.36946529 | E4: 0.36946529 | F4: 0.44504654
A5: 3 | B5: 1 | C5: 0.31804125 | E5: 0.31804125 | F5: 0.43576996
A6: 4 | B6: 1 | C6: 0.38956917 | E6: 0.38956917 | F6: 0.42692458
A7: 5 | B7: 1 | C7: 0.33850442 | E7: 0.33850442 | F7: 0.43408096
A8: 6 | B8: 1 | C8: 0.30894821 | E8: 0.30894821 | F8: 0.40829717
A9: 7 | B9: 1 | C9: 0.28531675 | E9: 0.28531675 | F9: 0.35277546
A10: 8 | B10: 1 | C10: 0.42035821 | E10: 0.42035821 | F10: 0.29063458
A11: 9 | B11: 1 | C11: 0.26063433 | E11: 0.26063433 | F11: 0.36896087
A12: 10 | B12: 1 | C12: 0.29397492 | E12: 0.29397492 | F12: 0.28329187
A13: 11 | B13: 1 | C13: 0.3499255 | E13: 0.3499255 | F13: 0.36328054
... A20: 18 | B20: 1 | C20: 0.22841404 | E20: 0.22841404 | F20: 0.39397054
A21: 19 | B21: 1 | C21: 0.25889271 | E21: 0.25889271 | F21: 0.43687788 | H21: Mean seqRT | I21: =AVERAGE(E2:E201) -> 0.32949494
A22: 20 | B22: 1 | C22: 0.26612679 | E22: 0.26612679 | F22: 0.39442475 | H22: Mean ranRT | I22: =AVERAGE(F2:F201) -> 0.50191944
A23: 21 | B23: 1 | C23: 0.40039671 | E23: 0.40039671 | F23: 0.41486425 | H23: Mean diff. | I23: =I22-I21 -> 0.1724245
A24: 22 | B24: 1 | C24: 0.32481496 | E24: 0.32481496 | F24: 0.46114062
A25: 23 | B25: 1 | C25: 0.25812475 | E25: 0.25812475 | F25: 0.43941167
A26: 24 | B26: 1 | C26: 0.27844171 | E26: 0.27844171
A27: 25 | B27: 1 | C27: 0.27092575 | E27: 0.27092575 | F27: 0.76781617
A28: 26 | B28: 1 | C28: 0.27204313 | E28: 0.27204313 | F28: 0.40857392
A29: 27 | B29: 1 | C29: 0.25885137 | E29: 0.25885137 | F29: 0.48147321
A30: 28 | B30: 1 | C30: 0.32720317 | E30: 0.32720317 | F30: 0.52506596
A31: 29 | B31: 1 | C31: 0.355879 | E31: 0.355879 | F31: 0.46368167
A32: 30 | B32: 1 | C32: 0.25616608 | E32: 0.25616608 | F32: 0.392927
A33: 31 | B33: 1 | C33: 0.29090263 | E33: 0.29090263 | F33: 0.39691687
A34: 32 | B34: 1 | C34: 0.27231317 | E34: 0.27231317 | F34: 0.40575771
A35: 33 | B35: 1 | C35: 0.27397108 | E35: 0.27397108 | F35: 0.45011896
A36: 34 | B36: 1 | C36: 0.22354308 | E36: 0.22354308 | F36: 0.54641288
A37: 35 | B37: 1 | C37: 0.27102583 | E37: 0.27102583 | F37: 0.30249075
A38: 36 | B38: 1 | C38: 0.30268896 | E38: 0.30268896 | F38: 0.43978021
... A41: 39 | B41: 1 | C41: 0.27708471 | E41: 0.27708471 | F41: 0.33412537
A42: 40 | B42: 1 | C42: 0.26355088 | E42: 0.26355088
A43: 41 | B43: 1 | C43: 0.29186317 | E43: 0.29186317 | F43: 0.47308879
A44: 42 | B44: 1 | C44: 0.27291154 | E44: 0.27291154 | F44: 0.31481992
A45: 43 | B45: 1 | C45: 0.30357167 | E45: 0.30357167 | F45: 0.34096179
A46: 44 | B46: 1 | C46: 0.29182242 | E46: 0.29182242 | F46: 0.65601117
A47: 45 | B47: 1 | C47: 0.32349525 | E47: 0.32349525 | F47: 0.31236983
A48: 46 | B48: 1 | C48: 0.27099871 | E48: 0.27099871 | F48: 0.37251796
...

Sheet P2
A1: thisN | B1: key_resp.corr | C1: key_resp.rt | E1: seqRT | F1: ranRT
A2: 0 | B2: 1 | C2: 0.49593742 | E2: 0.49593742 | F2: 0.44308287
A3: 1 | B3: 1 | C3: 0.33917142 | E3: 0.33917142 | F3: 0.54080221
A4: 2 | B4: 1 | C4: 0.54757417 | E4: 0.54757417 | F4: 0.44787617
A5: 3 | B5: 1 | C5: 0.31782017 | E5: 0.31782017 | F5: 0.22789858
A6: 4 | B6: 1 | C6: 0.32847317 | E6: 0.32847317 | F6: 0.38336333
A7: 5 | B7: 1 | C7: 0.33014237 | E7: 0.33014237 | F7: 0.35929079
A8: 6 | B8: 1 | C8: 0.28090933 | E8: 0.28090933 | F8: 0.22832675
A9: 7 | B9: 1 | C9: 0.36089946 | E9: 0.36089946 | F9: 0.28808679
A10: 8 | B10: 1 | C10: 0.4710825 | E10: 0.4710825 | F10: 0.31930083
A11: 9 | B11: 1 | C11: 0.33990346 | E11: 0.33990346 | F11: 0.22840642
A12: 10 | B12: 1 | C12: 0.40083567 | E12: 0.40083567 | F12: 0.26378496
A13: 11 | B13: 1 | C13: 0.46342462 | E13: 0.46342462 | F13: 0.44530033
... A15: 13 | B15: 1 | C15: 0.31544179 | E15: 0.31544179 | F15: 0.31312442
A16: 14 | B16: 1 | C16: 0.30021587 | E16: 0.30021587
A17: 15 | B17: 1 | C17: 0.35435067 | E17: 0.35435067 | F17: 0.43520829
A18: 16 | B18: 1 | C18: 0.36946225 | E18: 0.36946225 | F18: 0.32880321
A19: 17 | B19: 1 | C19: 0.30826483 | E19: 0.30826483
A20: 18 | B20: 1 | C20: 0.30344296 | E20: 0.30344296 | F20: 0.48949525 | H20: Mean seqRT | I20: =AVERAGE(E1:E201) -> 0.35340299
A21: 19 | B21: 1 | C21: 0.28290038 | E21: 0.28290038 | F21: 0.56850058 | H21: Mean ranRT | I21: =AVERAGE(F1:F201) -> 0.43284541
A22: 20 | B22: 1 | C22: 0.402005 | E22: 0.402005 | F22: 0.33431479 | H22: Mean diff. | I22: =I21-I20 -> 0.079442421
A23: 21 | B23: 1 | C23: 0.44204329 | E23: 0.44204329 | F23: 0.42170608
A24: 22 | B24: 1 | C24: 0.35454275 | E24: 0.35454275 | F24: 0.38528229
A25: 23 | B25: 1 | C25: 0.2995595 | E25: 0.2995595 | F25: 0.35188437
A26: 24 | B26: 1 | C26: 0.43949975 | E26: 0.43949975 | F26: 0.40468042
A27: 25 | B27: 1 | C27: 0.33354862 | E27: 0.33354862 | F27: 0.33817579
A28: 26 | B28: 1 | C28: 0.33707796 | E28: 0.33707796 | F28: 0.47387508
A29: 27 | B29: 1 | C29: 0.33467217 | E29: 0.33467217 | F29: 0.35947133
A30: 28 | B30: 1 | C30: 0.30995737 | E30: 0.30995737 | F30: 0.43476117
A31: 29 | B31: 1 | C31: 0.39166637 | E31: 0.39166637 | F31: 0.38879867
A32: 30 | B32: 1 | C32: 0.34308054 | E32: 0.34308054 | F32: 0.43421858
A33: 31 | B33: 1 | C33: 0.32478017 | E33: 0.32478017 | F33: 0.38899467
A34: 32 | B34: 1 | C34: 0.31732437 | E34: 0.31732437 | F34: 0.29377354
... A65: 63 | B65: 1 | C65: 0.273778 | E65: 0.273778 | F65: 0.34219183
A66: 64 | B66: 1 | C66: 0.34360625 | E66: 0.34360625
A67: 65 | B67: 1 | C67: 0.26414579 | E67: 0.26414579 | F67: 0.47694167
A68: 66 | B68: 1 | C68: 0.35234108 | E68: 0.35234108 | F68: 0.430446
A69: 67 | B69: 1 | C69: 0.37452921 | E69: 0.37452921 | F69: 0.48414671
A70: 68 | B70: 1 | C70: 0.27632929 | E70: 0.27632929 | F70: 0.3742175
A71: 69 | B71: 1 | C71: 0.29188483 | E71: 0.29188483 | F71: 0.56542958
...

Sheet P3
A1: thisN | B1: key_resp.corr | C1: key_resp.rt | E1: seqRT | F1: ranRT
A2: 0 | B2: 1 | C2: 0.53442704 | E2: 0.53442704 | F2: 0.49461117
A3: 1 | B3: 1 | C3: 0.31888487 | E3: 0.31888487 | F3: 0.33054117
A4: 2 | B4: 1 | C4: 0.29297896 | E4: 0.29297896 | F4: 0.44415462
A5: 3 | B5: 1 | C5: 0.45112212 | E5: 0.45112212 | F5: 0.53008612
A6: 4 | B6: 1 | C6: 0.32010637 | E6: 0.32010637 | F6: 0.62352871
A7: 5 | B7: 1 | C7: 0.38949692 | E7: 0.38949692 | F7: 0.43430479
A8: 6 | B8: 0 | F8: 0.48689996
A9: 7 | B9: 1 | C9: 0.52028842 | E9: 0.52028842 | F9: 0.54378846
A10: 8 | B10: 1 | C10: 0.49799579 | E10: 0.49799579 | F10: 0.48667046
A11: 9 | B11: 1 | C11: 0.31480471 | E11: 0.31480471 | F11: 0.47188737
A12: 10 | B12: 1 | C12: 0.33903025 | E12: 0.33903025 | F12: 0.49002133
A13: 11 | B13: 1 | C13: 0.48808187 | E13: 0.48808187 | F13: 0.31870767
A14: 12 | B14: 1 | C14: 0.39608125 | E14: 0.39608125 | F14: 0.34070442
A15: 13 | B15: 1 | C15: 0.37993183 | E15: 0.37993183 | F15: 0.44322288
A16: 14 | B16: 1 | C16: 0.270286 | E16: 0.270286 | F16: 0.31893171
A17: 15 | B17: 1 | C17: 0.30888962 | E17: 0.30888962
A18: 16 | B18: 1 | C18: 0.27424767 | E18: 0.27424767 | F18: 0.55931983
A19: 17 | B19: 1 | C19: 0.28379854 | E19: 0.28379854 | F19: 0.35152292
A20: 18 | B20: 1 | C20: 0.23581104 | E20: 0.23581104 | F20: 0.446879 | H20: Mean seqRT | I20: =AVERAGE(E1:E201) -> 0.32425772
A21: 19 | B21: 1 | C21: 0.29744029 | E21: 0.29744029 | F21: 0.44954679 | H21: Mean ranRT | I21: =AVERAGE(F1:F201) -> 0.43228424
A22: 20 | B22: 1 | C22: 0.35636642 | E22: 0.35636642 | F22: 0.52577654 | H22: Mean diff. | I22: =I21-I20 -> 0.10802652
A23: 21 | B23: 1 | C23: 0.33355617 | E23: 0.33355617 | F23: 0.39359488
A24: 22 | B24: 1 | C24: 0.26591812 | E24: 0.26591812 | F24: 0.37940321
A25: 23 | B25: 1 | C25: 0.33113662 | E25: 0.33113662 | F25: 0.52594917
A26: 24 | B26: 1 | C26: 1.0833748 | E26: 1.0833748 | F26: 0.48253296
A27: 25 | B27: 1 | C27: 0.42336188 | E27: 0.42336188 | F27: 0.37313904
A28: 26 | B28: 1 | C28: 0.44363304 | E28: 0.44363304 | F28: 0.48985421
A29: 27 | B29: 1 | C29: 0.31451329 | E29: 0.31451329 | F29: 0.42371921
A30: 28 | B30: 1 | C30: 0.28761813 | E30: 0.28761813 | F30: 0.40042375
A31: 29 | B31: 1 | C31: 0.28306021 | E31: 0.28306021 | F31: 0.42834071
A32: 30 | B32: 1 | C32: 0.23658083 | E32: 0.23658083 | F32: 0.48684458
A33: 31 | B33: 1 | C33: 0.30563012 | E33: 0.30563012 | F33: 0.3310755
A34: 32 | B34: 1 | C34: 0.35340912 | E34: 0.35340912 | F34: 0.5326265
... A49: 47 | B49: 1 | C49: 0.28116771 | E49: 0.28116771 | F49: 0.41783167
A50: 48 | B50: 1 | C50: 0.31311092 | E50: 0.31311092
A51: 49 | B51: 1 | C51: 0.27389933 | E51: 0.27389933 | F51: 0.44392142
A52: 50 | B52: 1 | C52: 0.24239258 | E52: 0.24239258 | F52: 0.40278563
A53: 51 | B53: 1 | C53: 0.30646721 | E53: 0.30646721 | F53: 0.36609208
A54: 52 | B54: 0 | F54: 0.35824892
...

Sheet P4
A1: thisN | B1: key_resp.corr | C1: key_resp.rt | E1: seqRT | F1: ranRT
A2: 0 | B2: 1 | C2: 0.44849342 | E2: 0.44849342 | F2: 0.49889312
A3: 1 | B3: 1 | C3: 0.29273213 | E3: 0.29273213 | F3: 0.29373467
A4: 2 | B4: 1 | C4: 0.2544475 | E4: 0.2544475 | F4: 0.30679308
A5: 3 | B5: 1 | C5: 0.25777208 | E5: 0.25777208 | F5: 0.45708808
A6: 4 | B6: 1 | C6: 0.43361563 | E6: 0.43361563 | F6: 0.36036358
A7: 5 | B7: 1 | C7: 0.42797433 | E7: 0.42797433 | F7: 0.46067529
A8: 6 | B8: 1 | C8: 0.22579587 | E8: 0.22579587 | F8: 0.53992504
A9: 7 | B9: 1 | C9: 0.33049075 | E9: 0.33049075 | F9: 0.37884454
A10: 8 | B10: 1 | C10: 0.42314542 | E10: 0.42314542 | F10: 0.30636087
A11: 9 | B11: 1 | C11: 0.31178196 | E11: 0.31178196 | F11: 0.45986942
A12: 10 | B12: 1 | C12: 0.41111112 | E12: 0.41111112 | F12: 0.52908288
A13: 11 | B13: 1 | C13: 0.43316237 | E13: 0.43316237 | F13: 0.44861692
... A19: 17 | B19: 1 | C19: 0.32271246 | E19: 0.32271246 | F19: 0.44855288
A20: 18 | B20: 1 | C20: 0.29018071 | E20: 0.29018071 | F20: 0.44838483 | H20: Mean seqRT | I20: =AVERAGE(E1:E201) -> 0.3355465
A21: 19 | B21: 1 | C21: 0.29840817 | E21: 0.29840817 | F21: 0.52382375 | H21: Mean ranRT | I21: =AVERAGE(F1:F201) -> 0.45399693
A22: 20 | B22: 1 | C22: 0.30023917 | E22: 0.30023917 | F22: 0.46644271 | H22: Mean diff. | I22: =I21-I20 -> 0.11845044
A23: 21 | B23: 1 | C23: 0.30012746 | E23: 0.30012746 | F23: 0.608668
A24: 22 | B24: 1 | C24: 0.30245567 | E24: 0.30245567 | F24: 0.35796004
A25: 23 | B25: 1 | C25: 0.25125492 | E25: 0.25125492 | F25: 0.27641171
A26: 24 | B26: 1 | C26: 0.29735083 | E26: 0.29735083 | F26: 0.51900104
A27: 25 | B27: 1 | C27: 0.33456462 | E27: 0.33456462 | F27: 0.63916925
A28: 26 | B28: 1 | C28: 0.30716338 | E28: 0.30716338 | F28: 0.66822488
A29: 27 | B29: 1 | C29: 0.31936375 | E29: 0.31936375 | F29: 0.513043
A30: 28 | B30: 1 | C30: 0.25836763 | E30: 0.25836763 | F30: 0.55807958
A31: 29 | B31: 1 | C31: 0.29318246 | E31: 0.29318246 | F31: 0.44011117
A32: 30 | B32: 1 | C32: 0.31422954 | E32: 0.31422954 | F32: 0.334902
A33: 31 | B33: 1 | C33: 0.2573745 | E33: 0.2573745 | F33: 0.40118471
A34: 32 | B34: 1 | C34: 0.28471208 | E34: 0.28471208 | F34: 0.81897179
... A50: 48 | B50: 1 | C50: 0.3218845 | E50: 0.3218845 | F50: 0.55289858
A51: 49 | B51: 0 | F51: 0.30393817
A52: 50 | B52: 1 | C52: 0.46088529 | E52: 0.46088529 | F52: 0.34114071
A53: 51 | B53: 1 | C53: 0.26901954 | E53: 0.26901954 | F53: 0.360834
A54: 52 | B54: 1 | C54: 0.30366737 | E54: 0.30366737 | F54: 0.35909329
A55: 53 | B55: 1 | C55: 0.29375133 | E55: 0.29375133 | F55: 0.51857221
A56: 54 | B56: 1 | C56: 0.26349996 | E56: 0.26349996
A57: 55 | B57: 1 | C57: 0.38220379 | E57: 0.38220379 | F57: 0.38353617
A58: 56 | B58: 1 | C58: 0.41027571 | E58: 0.41027571 | F58: 0.43567004
A59: 57 | B59: 1 | C59: 0.32550579 | E59: 0.32550579 | F59: 0.36004817
A60: 58 | B60: 1 | C60: 0.24750575 | E60: 0.24750575 | F60: 0.55342317
...

Sheet P5
A1: thisN | B1: key_resp.corr | C1: key_resp.rt | E1: seqRT | F1: ranRT
A2: 0 | B2: 1 | C2: 1.2480992 | E2: 1.2480992 | F2: 0.67963296
A3: 1 | B3: 1 | C3: 0.27590117 | E3: 0.27590117 | F3: 0.35985954
A4: 2 | B4: 1 | C4: 0.29559125 | E4: 0.29559125 | F4: 0.38437683
A5: 3 | B5: 1 | C5: 0.28422562 | E5: 0.28422562 | F5: 0.45256767
A6: 4 | B6: 1 | C6: 0.38611704 | E6: 0.38611704 | F6: 0.367329
A7: 5 | B7: 1 | C7: 0.28406804 | E7: 0.28406804 | F7: 0.61837979
A8: 6 | B8: 1 | C8: 0.28911604 | E8: 0.28911604 | F8: 0.42108892
A9: 7 | B9: 1 | C9: 0.383692 | E9: 0.383692 | F9: 0.41087446
A10: 8 | B10: 1 | C10: 0.32516442 | E10: 0.32516442 | F10: 0.45768412
A11: 9 | B11: 1 | C11: 0.25510692 | E11: 0.25510692 | F11: 0.52511987
A12: 10 | B12: 1 | C12: 0.39123288 | E12: 0.39123288 | F12: 0.49877987
A13: 11 | B13: 1 | C13: 0.29533996 | E13: 0.29533996 | F13: 0.32780629
... A19: 17 | B19: 1 | C19: 0.30188121 | E19: 0.30188121 | F19: 0.44171596
A20: 18 | B20: 1 | C20: 0.29227642 | E20: 0.29227642 | F20: 0.62764087 | H20: Mean seqRT | I20: =AVERAGE(E1:E201) -> 0.33899765
A21: 19 | B21: 1 | C21: 0.31894521 | E21: 0.31894521 | F21: 0.482254 | H21: Mean ranRT | I21: =AVERAGE(F1:F201) -> 0.43239819
A22: 20 | B22: 1 | C22: 0.2987665 | E22: 0.2987665 | F22: 0.48477062 | H22: Mean diff. | I22: =I21-I20 -> 0.093400538
A23: 21 | B23: 1 | C23: 0.33338875 | E23: 0.33338875 | F23: 0.37837017
A24: 22 | B24: 1 | C24: 0.25386621 | E24: 0.25386621 | F24: 0.4738795
A25: 23 | B25: 1 | C25: 0.27691275 | E25: 0.27691275 | F25: 0.36568667
A26: 24 | B26: 1 | C26: 0.3235605 | E26: 0.3235605 | F26: 0.37594296
A27: 25 | B27: 1 | C27: 0.50929946 | E27: 0.50929946 | F27: 0.34670879
A28: 26 | B28: 1 | C28: 0.27649475 | E28: 0.27649475 | F28: 0.45662133
A29: 27 | B29: 1 | C29: 0.28218133 | E29: 0.28218133 | F29: 0.51288504
A30: 28 | B30: 1 | C30: 0.25475471 | E30: 0.25475471
A31: 29 | B31: 1 | C31: 0.41223962 | E31: 0.41223962 | F31: 0.46889133
A32: 30 | B32: 1 | C32: 0.28847021 | E32: 0.28847021 | F32: 0.33659833
A33: 31 | B33: 1 | C33: 0.21712658 | E33: 0.21712658 | F33: 0.47860546
A34: 32 | B34: 1 | C34: 0.28899467 | E34: 0.28899467 | F34: 0.42268358
A35: 33 | B35: 1 | C35: 0.39437296 | E35: 0.39437296
A36: 34 | B36: 1 | C36: 0.26518433 | E36: 0.26518433
A37: 35 | B37: 1 | C37: 0.28144517 | E37: 0.28144517 | F37: 0.32664867
A38: 36 | B38: 1 | C38: 0.27210887 | E38: 0.27210887 | F38: 0.44656708
A39: 37 | B39: 1 | C39: 0.25561479 | E39: 0.25561479 | F39: 0.42633079
A40: 38 | B40: 1 | C40: 0.21602004 | E40: 0.21602004 | F40: 0.36201487
A41: 39 | B41: 1 | C41: 0.32942588 | E41: 0.32942588 | F41: 0.38630638
A42: 40 | B42: 1 | C42: 0.28001771 | E42: 0.28001771 | F42: 0.58077896
A43: 41 | B43: 1 | C43: 0.24238512 | E43: 0.24238512 | F43: 0.47776104
A44: 42 | B44: 1 | C44: 0.30358542 | E44: 0.30358542 | F44: 0.37432592
A45: 43 | B45: 1 | C45: 0.38618871 | E45: 0.38618871 | F45: 0.38562887
...

Sheet All particpant data 
A1: Participant | B1: Sequential RT | C1: Random RT | D1: Mean diffrence
A2: P1 | B2: ='P1'!I21 -> 0.32949494 | C2: ='P1'!I22 -> 0.50191944 | D2: ='P1'!I23 -> 0.1724245
A3: P2 | B3: ='P2'!I20 -> 0.35340299 | C3: ='P2'!I21 -> 0.43284541 | D3: ='P2'!I22 -> 0.079442421
A4: P3 | B4: ='P3'!I20 -> 0.32425772 | C4: ='P3'!I21 -> 0.43228424 | D4: ='P3'!I22 -> 0.10802652
A5: P4 | B5: ='P4'!I20 -> 0.3355465 | C5: ='P4'!I21 -> 0.45399693 | D5: ='P4'!I22 -> 0.11845044
A6: P5 | B6: ='P5'!I20 -> 0.33899765 | C6: ='P5'!I21 -> 0.43239819 | D6: ='P5'!I22 -> 0.093400538
A7: MEAN | B7: =AVERAGE(B2:B6) -> 0.33633996 | C7: =AVERAGE(C2:C6) -> 0.45068884 | D7: =C7-B7 -> 0.11434888
